<?xml version="1.0" encoding="utf-8"?>

<robot name="robot">

    <material name="black">
        <color rgba="0 0 0 1"/>
    </material>
    <material name="red">
        <color rgba="0.8 0.1 0.1 1"/>
    </material>
    <material name="blue">
        <color rgba="0.1 0.1 0.9 1"/>
    </material>
    <material name="white">
        <color rgba="1 1 1 1"/>
    </material>

    <link name="base_link">
        <origin rpy="0.0 0.0 0.0" xyz="0 0 0.00"/>
        <visual>
            <!-- <origin rpy="0.0 0.0 0.0" xyz="0.0 0.0 0.0"/> -->
            <geometry>
                <box size="5 5 0.001"/>
            </geometry>
        </visual>
        <collision>
            <!-- <origin rpy="0.0 0.0 0.0" xyz="0.0 0.0 0.0"/> -->
            <geometry>
                <box size="5 5 0.001"/>
            </geometry>
        </collision>
    </link>


    <link name="bot_x">
        <origin rpy="0.0 0.0 0.0" xyz="0.0 0.0 0.0"/>
    </link>

    <link name="bot">
        <visual>
            <origin rpy="0.0 0.0 0.0" xyz="0 0 0.03"/>
            <geometry>
                <cylinder radius="0.05" length="0.05"/>
            </geometry>
            <material name="">
                <color rgba="0.8 0.1 0.1 1"/>
            </material>
        </visual>
        <collision>
            <origin rpy="0.0 0.0 0.0" xyz="0 0 0.03"/>
            <geometry>
                <cylinder radius="0.05" length="0.05"/>
            </geometry>
        </collision>
        <inertial>
            <origin xyz="0 0 0" rpy="0 0 0"/>
            <mass value="0.2"/>
        </inertial>
    </link>

    <joint name="base_to_bot_x" type="prismatic">
        <parent link="base_link"/>
        <child link="bot_x"/>
        <origin rpy="0 0 0" xyz="0 0 0.01"/>
        <axis xyz="1 0 0"/>
    </joint>

    <joint name="bot_x_to_bot" type="prismatic">
        <parent link="bot_x"/>
        <child link="bot"/>
        <origin rpy="0 0 0" xyz="0 0 0.01"/>
        <axis xyz="0 1 0"/>
    </joint>

</robot>